Workbook

Sheet Sheet1
A1: Hollow | D1: GPNA | G1: GPRAC-25 | J1: GPRAC-50 | M1: GPRAC-75 | P1: GPRAC-100
A2: Force | B2: Strain | D2: Force | E2: Strain | G2: Force | H2: Strain | J2: Force | K2: Strain | M2: Force | N2: Strain | P2: Force | Q2: Strain
A3: kN | B3: μ | D3: KN | E3: μ | G3: KN | H3: μ | J3: KN | K3: μ | M3: KN | N3: μ | P3: KN | Q3: μ
A4: 0 | B4: 0 | D4: 0 | E4: 0 | G4: 0 | H4: 0 | J4: 0 | K4: 0 | M4: 0 | N4: 0 | P4: 0 | Q4: 0
A5: 10 | B5: 12 | D5: 11.8 | E5: 17 | G5: 11.8 | H5: -8 | J5: 11.8 | K5: 6 | M5: 11.8 | N5: 4 | P5: 11.8 | Q5: 0
A6: 20 | B6: 48 | D6: 23.6 | E6: 40 | G6: 23.6 | H6: -9 | J6: 23.6 | K6: 22 | M6: 23.6 | N6: 13 | P6: 23.6 | Q6: 1.5
A7: 30 | B7: 144 | D7: 35.4 | E7: 66 | G7: 35.4 | H7: -11 | J7: 35.4 | K7: 34 | M7: 35.4 | N7: 21 | P7: 35.4 | Q7: 11.5
A8: 40 | B8: 234 | D8: 47.2 | E8: 90 | G8: 47.2 | H8: -17 | J8: 47.2 | K8: 45 | M8: 47.2 | N8: 27 | P8: 47.2 | Q8: 30
A9: 50 | B9: 299 | D9: 59 | E9: 116 | G9: 59 | H9: -20 | J9: 59 | K9: 56 | M9: 59 | N9: 35 | P9: 59.055312 | Q9: 57.5
A10: 60 | B10: 363 | D10: 70.8 | E10: 137 | G10: 70.8 | H10: -23 | J10: 59.07375 | K10: 58 | M10: 59.129068 | N10: 34 | P10: 70.87375 | Q10: 93.5
A11: 70 | B11: 503 | D11: 82.6 | E11: 155 | G11: 82.6 | H11: -25 | J11: 59.295 | K11: 58 | M11: 59.165943 | N11: 34 | P11: 82.6 | Q11: 136
A12: 80 | B12: 662 | D12: 94.4 | E12: 137 | G12: 94.4 | H12: -24 | J12: 59.313443 | K12: 57 | M12: 59.22125 | N12: 34 | P12: 94.436875 | Q12: 181.5
A13: 90 | B13: 731 | D13: 106.2 | E13: 155 | G13: 106.2 | H13: -19 | J13: 59.405625 | K13: 57 | M13: 59.36875 | N13: 35 | P13: 106.20922 | Q13: 230.5
A14: 90.0625 | B14: 731 | D14: 118 | E14: 176 | G14: 118 | H14: -14 | J14: 59.553125 | K14: 57 | M14: 59.497818 | N14: 34 | P14: 118.04608 | Q14: 284
A15: 90.10938 | B15: 732 | D15: 118.09216 | E15: 176 | G15: 118.01841 | H15: -14 | J15: 59.66375 | K15: 58 | M15: 59.571568 | N15: 35 | P15: 118.11989 | Q15: 283.5
... A1446: 192.375 | B1446: 2364 | D1446: 363.97466 | E1446: 1356 | G1446: 315.53943 | H1446: 1021 | J1446: 235.79716 | K1446: 495 | M1446: 211.62568 | N1446: 348 | P1446: 306.91062 | Q1446: 2180.5
D1447: 364.12216 | E1447: 1358 | G1447: 315.63159 | H1447: 1022 | J1447: 235.96318 | K1447: 495 | M1447: 211.68091 | N1447: 349 | P1447: 306.9383 | Q1447: 2182
D1448: 364.30659 | E1448: 1359 | G1448: 315.74216 | H1448: 1025 | J1448: 236.03693 | K1448: 496 | M1448: 211.79159 | N1448: 350 | P1448: 307.03966 | Q1448: 2183
D1449: 364.49091 | E1449: 1361 | G1449: 315.83443 | H1449: 1025 | J1449: 236.12909 | K1449: 496 | M1449: 211.90216 | N1449: 351 | P1449: 307.11347 | Q1449: 2184
D1450: 364.67534 | E1450: 1362 | G1450: 315.945 | H1450: 1028 | J1450: 236.22125 | K1450: 496 | M1450: 211.99443 | N1450: 352 | P1450: 307.2333 | Q1450: 2186.5
D1451: 364.84125 | E1451: 1363 | G1451: 316.11091 | H1451: 1029 | J1451: 236.36875 | K1451: 497 | M1451: 212.06818 | N1451: 352 | P1451: 307.27017 | Q1451: 2188
D1452: 365.09943 | E1452: 1366 | G1452: 316.14784 | H1452: 1031 | J1452: 236.4425 | K1452: 497 | M1452: 212.14193 | N1452: 353 | P1452: 307.33472 | Q1452: 2189.5
D1453: 365.22841 | E1453: 1367 | G1453: 316.36909 | H1453: 1033 | J1453: 236.64534 | K1453: 497 | M1453: 212.28943 | N1453: 353 | P1453: 307.41767 | Q1453: 2191
D1454: 365.3575 | E1454: 1369 | G1454: 316.40591 | H1454: 1034 | J1454: 236.66375 | K1454: 498 | M1454: 212.36318 | N1454: 354 | P1454: 307.51909 | Q1454: 2193
D1455: 365.56034 | E1455: 1371 | G1455: 316.51659 | H1455: 1036 | J1455: 236.84818 | K1455: 498 | M1455: 212.52909 | N1455: 355 | P1455: 307.59284 | Q1455: 2193.5
D1456: 365.72625 | E1456: 1371 | G1456: 316.64568 | H1456: 1037 | J1456: 236.885 | K1456: 498 | M1456: 212.5475 | N1456: 356 | P1456: 307.71267 | Q1456: 2195.5
D1457: 365.91068 | E1457: 1374 | G1457: 316.77466 | H1457: 1039 | J1457: 237.05091 | K1457: 500 | M1457: 212.65818 | N1457: 356 | P1457: 307.84176 | Q1457: 2199
D1458: 366.095 | E1458: 1376 | G1458: 316.84841 | H1458: 1040 | J1458: 237.18 | K1458: 499 | M1458: 212.71341 | N1458: 357 | P1458: 307.92472 | Q1458: 2200
... D2172: 444.08568 | E2172: 3250 | G2172: 333.31318 | H2172: 2929 | J2172: 310.93 | K2172: 741 | M2172: 282.62841 | N2172: 1148 | P2172: 333.18403 | Q2172: 3547
D2173: 444.08568 | E2173: 3254 | J2173: 311.05909 | K2173: 741 | M2173: 282.70216 | N2173: 1149 | P2173: 333.15642 | Q2173: 3528
D2174: 444.06716 | E2174: 3257 | J2174: 311.16966 | K2174: 741 | M2174: 282.84966 | N2174: 1151 | P2174: 333.09187 | Q2174: 3510
D2175: 444.04875 | E2175: 3260 | J2175: 311.24341 | K2175: 742 | M2175: 282.92341 | N2175: 1152 | P2175: 333.11955 | Q2175: 3491.5
D2176: 444.04875 | E2176: 3263 | J2176: 311.28034 | K2176: 743 | M2176: 283.03409 | N2176: 1153 | P2176: 333.03659 | Q2176: 3471
D2177: 444.01193 | E2177: 3265 | J2177: 311.44625 | K2177: 742 | M2177: 283.14466 | N2177: 1154
D2178: 444.01193 | E2178: 3269 | J2178: 311.53841 | K2178: 743 | M2178: 283.16318 | N2178: 1155
D2179: 443.99341 | E2179: 3272 | J2179: 311.6675 | K2179: 744 | M2179: 283.29216 | N2179: 1157
D2180: 444.01193 | E2180: 3276 | J2180: 311.70443 | K2180: 744 | M2180: 283.40284 | N2180: 1158
D2181: 443.975 | E2181: 3277 | J2181: 311.815 | K2181: 744 | M2181: 283.53193 | N2181: 1160
D2182: 444.04875 | E2182: 3281 | J2182: 311.90716 | K2182: 744 | M2182: 283.67943 | N2182: 1161
D2183: 443.975 | E2183: 3284 | J2183: 311.9625 | K2183: 745 | M2183: 283.73466 | N2183: 1162
...

Sheet Graphs
B3: Hollow | C3: =MAX(Sheet1!A:A) -> 195.1719 | D3: 444.19625 | F3: =(D3-C3)/C3 -> 1.2759232
B4: GPNA | C4: 444.19625 | D4: 444.19625
B5: GPRAC-25 | C5: 364.03 | D5: 444.19625 | E5: =D5-C5 -> 80.16625 | F5: =(D5-C5)/D5 -> 0.18047485
B6: GPRAC-50 | C6: 361.63318 | D6: 444.19625 | E6: =D6-C6 -> 82.563066 | F6: =(D6-C6)/D6 -> 0.1858707
B7: GPRAC-75 | C7: 354.7375 | D7: 444.19625 | E7: =D7-C7 -> 89.45875 | F7: =(D7-C7)/D7 -> 0.20139465
B8: GPRAC-100 | C8: 340.52222 | D8: 444.19625 | E8: =D8-C8 -> 103.67403 | F8: =(D8-C8)/D8 -> 0.23339691
C21: Stress | D21: Load | E21: Area
B22: Hollow | C22: =(D22*1000)/E22 -> 13.760004 | D22: =MAX(Sheet1!A4:A80000) -> 195.1719 | E22: 14184
B23: GPNA | C23: =(D23*1000)/E23 -> 31.316712 | D23: =MAX(Sheet1!D4:D80000) -> 444.19625 | E23: 14184
B24: GPRAC-25 | C24: =(D24*1000)/E24 -> 25.664834 | D24: =MAX(Sheet1!G4:G80000) -> 364.03 | E24: 14184
B25: GPRAC-50 | C25: =(D25*1000)/E25 -> 25.495853 | D25: =MAX(Sheet1!J4:J80000) -> 361.63318 | E25: 14184
B26: GPRAC-75 | C26: =(D26*1000)/E26 -> 25.009694 | D26: =MAX(Sheet1!M4:M80000) -> 354.7375 | E26: 14184
B27: GPRAC-100 | C27: =(D27*1000)/E27 -> 24.007489 | D27: =MAX(Sheet1!P4:P80000) -> 340.52222 | E27: 14184
B30: Factor = 1.18
